Workbook
Name Account_Endorse: 'Ref Select'!$A$1:$A$72
Name Attitude: 'Ref Select'!$P$2:$P$5
Name Check: 'Ref Select'!$W$2:$W$3
Name Choosing: 'Ref Select'!$I$1:$I$15
Name ClientDispo: 'Ref Select'!$T$2:$T$5
Name Course: 'Ref Select'!$H$1:$H$43
Name CPA: 'Ref Select'!$V$2:$V$5
Name Degree: 'Ref Select'!$G$1:$G$10
Name Essay: 'Ref Select'!$Q$2:$Q$5
Name Gender: 'Ref Select'!$C$1:$C$3
Name HOLDREJECT: 'Ref Select'!$N$2:$N$21
Name JO: 'Ref Select'!$AF$1:$AF$36
Name Number: 'Ref Select'!$E$2:$E$17
Name OPSDispo: 'Ref Select'!$S$2:$S$6
Name OpsInter: 'Ref Select'!$S$2:$S$6
Name PA: 'Ref Select'!$O$2:$O$6
Name Reason: 'Ref Select'!$X$2:$X$22
Name Recomendation: 'Ref Select'!$M$2:$M$7
Name Source_Applicant: 'Ref Select'!$B$1:$B$28
Name Transpo: 'Ref Select'!$K$1:$K$10
Name Verbal: 'Ref Select'!$R$2:$R$5
Name YESNO: 'Ref Select'!$D$2:$D$4
Name YNN: 'Ref Select'!$J$2:$J$4

Sheet For HR use only
B1: Form>> Autofill based on Recruitment form | C1: Details | E1: QB Form | F1: Staff Requisitions- Autofilled? | G1: Remarks | J1: Applicants :
B2: Last Name | C2: =IF(ISBLANK('Personal Information'!A8),"",'Personal Information'!A8) | F2: Current Day
B3: Maiden Name | C3: =IF(OR('Personal Information'!C8="N/A",'Personal Information'!C8="NA"),"",IF(ISBLANK('Personal Information'!C8),"",'Personal Information'!C8)) | F3: Requisition Month | J3: Applicant Background Form | K3: Details | L3: Remarks
B4: First Name | C4: =IF(ISBLANK('Personal Information'!E8),"",'Personal Information'!E8) | F4: Color | J4: Job Opening # | K4: 295 | L4: Manual- Required to fill
B5: Middle Name | C5: =IF(ISBLANK('Personal Information'!G8),"",'Personal Information'!G8) | F5: Reviewed by Talent Acquisition: | J5: Current Day | K5: 44498 | L5: Enter date manually
B6: Nickname | C6: =IF(ISBLANK('Personal Information'!I8),"",'Personal Information'!I8) | F6: Job Title: * | J6: Recruiting For: | K6: Senior Accountant | L6: Manual- Required to fill
B7: Present Address | C7: =IF(ISBLANK('Personal Information'!A10),"",'Personal Information'!A10) | F7: Grade Level | J7: Account endorsed to | K7: Tony Auto Group | L7: Manual- Required to Select
B8: Permanent Address | C8: =IF(ISBLANK('Personal Information'!F10),"",'Personal Information'!F10) | F8: Other Position Titles | J8: Position: | K8: Senior Accountant | L8: Manual- Required to fill
B9: Contact Number(s) | C9: =IF(ISBLANK('Personal Information'!A19),"",'Personal Information'!A19) | F9: Assignment/Client: * | J9: Application Date | K9: 44468 | L9: Enter date manually
B10: Email Address | C10: =IF(ISBLANK('Personal Information'!F19),"",'Personal Information'!F19) | F10: Number of Job openings | J10: Source of Applicant * | K10: Jobstreet | L10: Manual- Required to Select
B11: Current Monthly Salary | C11: =IF(ISBLANK('Personal Information'!C20),"",'Personal Information'!C20) | F11: Search Action Level * | J11: =IF($K$10="Indeed.com","Sponsored?*",_xlfn.IFNA(IF($K$10=VLOOKUP($K$10,'Ref Select'!$U$2:$U$9,1,0),"Referred by:*",""),"")) | L11: Manual- Required to fill if referred, Select if sponsor
B12: Expected Salary | C12: =IF(ISBLANK('Personal Information'!C21),"",'Personal Information'!C21) | F12: Location Authorized * | J12: Last Name * | K12: =IF(OR(C2=0,C2=""),"",C2) | L12: Autofill from Personal information
B13: Date Available (please specify Notice Period) | C13: =IF(ISBLANK('Personal Information'!C22),"",'Personal Information'!C22) | F13: Why Urgent or Expedite?* | J13: First Name * | K13: =IF(OR(C4=0,C4=""),"",C4) | L13: Autofill from Personal information
B14: The following conditions may be required at some point in your employment. Are you amenable to working: | F14: Position Needed by* | J14: Middle Name | K14: =IF(OR(C5=0,C5=""),"",C5) | L14: Autofill from Personal information
B15: Shifts | F15: Direct Supervisor: | J15: Nick Name | K15: =IF(OR(C6=0,C6=""),"",C6) | L15: Autofill from Personal information
B16: Graveyard Shift | C16: =IF(ISBLANK('Personal Information'!G23),"",'Personal Information'!G23) | F16: Department: | J16: Gender * | K16: =IF(OR(C28=0,C28=""),"",C28) | L16: Autofill from Personal information
B17: Rotation Schedule | C17: =IF(ISBLANK('Personal Information'!G24),"",'Personal Information'!G24) | F17: Department Head: | J17: Date of Birth | K17: =IF(OR(C26=0,C26=""),"",C26 ) | L17: Autofill from Personal information
B18: Overtime | C18: =IF(ISBLANK('Personal Information'!G25),"",'Personal Information'!G25) | F18: Search Classification * | J18: Age (In Years) | K18: =IF(ISTEXT(K17),"",(YEAR(TODAY())-YEAR(K17))) | L18: Calculated field
B19: Holidays | C19: =IF(ISBLANK('Personal Information'!G26),"",'Personal Information'!G26) | F19: Date Open: | J19: Head of Household * | K19: =IF(ISBLANK(VLOOKUP($J19,'Additional Information'!$A:$B,2,0)),"",_xlfn.IFNA(VLOOKUP($J19,'Additional Information'!$A:$B,2,0),"")) | L19: Autofill from Additional information
B20: Type of Employment | C20: =IF(ISBLANK('Personal Information'!H21),"",'Personal Information'!H21) | F20: Target Hire Date: | J20: Number of Dependents * | K20: =IF(ISBLANK(VLOOKUP($J20,'Additional Information'!$A:$B,2,0)),"",_xlfn.IFNA(VLOOKUP($J20,'Additional Information'!$A:$B,2,0),"")) | L20: Autofill from Additional information
B21: How did you know about us? | C21: =IF('Personal Information'!H23="others","Others | "&" "&SUBSTITUTE('Personal Information'!H25,"Please Specify: ",""),'Personal Information'!H23) -> 0 | F21: Planned Search Duration (Days) | J21: Date Willing to Start * | K21: =IF(ISBLANK(VLOOKUP($J21,'Additional Information'!$A:$B,2,0)),"",_xlfn.IFNA(VLOOKUP($J21,'Additional Information'!$A:$B,2,0),"")) | L21: Autofill from Additional information
B22: Government Numbers | F22: Base Compensation (Min): * | J22: Resume Attachment | K22: Yes | L22: Manual- Required to Select
B23: SSS Number | C23: =IF(ISBLANK('Personal Information'!C24),"",'Personal Information'!C24) | F23: Grade Midpoint | J23: Start Date on Last Job | K23: =IF(ISBLANK(VLOOKUP($J23,'Additional Information'!$A:$B,2,0)),"",_xlfn.IFNA(VLOOKUP($J23,'Additional Information'!$A:$B,2,0),"")) | L23: Autofill from Additional information | N23: Background color legend:
B24: Tin | C24: =IF(ISBLANK('Personal Information'!C25),"",'Personal Information'!C25) | F24: Average Salary in Account * | J24: End Date on Last Job | K24: =IF(ISBLANK(VLOOKUP($J24,'Additional Information'!$A:$B,2,0)),"",_xlfn.IFNA(VLOOKUP($J24,'Additional Information'!$A:$B,2,0),"")) | L24: Autofill from Additional information | N24: GREY : Manual Entry of data/details
B25: Pag Ibig | C25: =IF(ISBLANK('Personal Information'!C26),"",'Personal Information'!C26) | F25: Highest Salary in Account * | J25: Still with Last Employer | K25: =IF(ISBLANK(VLOOKUP($J25,'Additional Information'!$A:$B,2,0)),"",_xlfn.IFNA(VLOOKUP($J25,'Additional Information'!$A:$B,2,0),"")) | L25: Autofill from Additional information | N25: WHITE: Auto fill based on Personal information tab
B26: Date of Birth | C26: =IF(ISBLANK('Personal Information'!A28),"",'Personal Information'!A28) | F26: Salary Offered | J26: Application Attachment | K26: Yes | L26: Manual- Required to Select
B27: Citizenship | C27: =IF(ISBLANK('Personal Information'!C28),"",'Personal Information'!C28) | F27: Referral Bonus | J27: Number of Jobs in Last 3 Years * | K27: =IF(ISBLANK(VLOOKUP($J27,'Additional Information'!$A:$B,2,0)),"",_xlfn.IFNA(VLOOKUP($J27,'Additional Information'!$A:$B,2,0),"")) | L27: Autofill from Additional information
B28: Gender | C28: =IF(ISBLANK('Personal Information'!F28),"",'Personal Information'!F28) | F28: Hiring Bonus: | J28: Reason for Leaving Last Job | K28: =IF(ISBLANK(VLOOKUP($J28,'Additional Information'!$A:$B,2,0)),"",_xlfn.IFNA(VLOOKUP($J28,'Additional Information'!$A:$B,2,0),"")) | L28: Autofill from Additional information
B29: Civil Status | C29: =IF(ISBLANK('Personal Information'!H28),"",'Personal Information'!H28) | F29: Bonus Potential: | J29: Notice Period (Days) | K29: =IF(ISBLANK(VLOOKUP($J29,'Additional Information'!$A:$B,2,0)),"",_xlfn.IFNA(VLOOKUP($J29,'Additional Information'!$A:$B,2,0),"")) | L29: Autofill from Additional information
B30: EDUCATIONAL BACKGROUND | F30: Planned Schedule: | J30: High School Graduate | K30: =IF(ISBLANK(VLOOKUP($J30,'Additional Information'!$A:$B,2,0)),"",_xlfn.IFNA(VLOOKUP($J30,'Additional Information'!$A:$B,2,0),"")) | L30: Autofill from Additional information
B31: Secondary | F31: Direct Experience Field | J31: Attended College | K31: =IF(ISBLANK(VLOOKUP($J31,'Additional Information'!$A:$B,2,0)),"",_xlfn.IFNA(VLOOKUP($J31,'Additional Information'!$A:$B,2,0),"")) | L31: Autofill from Additional information
B32: Degree/Course | C32: =IF(ISBLANK('Personal Information'!G30),"",'Personal Information'!G30) | F32: Years Direct Experience Required | J32: College Graduate | K32: =IF(ISBLANK(VLOOKUP($J32,'Additional Information'!$A:$B,2,0)),"",_xlfn.IFNA(VLOOKUP($J32,'Additional Information'!$A:$B,2,0),"")) | L32: Autofill from Additional information
B33: Inclusive Dates | C33: =IF(ISBLANK('Personal Information'!I30),"",'Personal Information'!I30) | F33: Job Description | J33: Degree Obtained | K33: =IF(ISBLANK(VLOOKUP($J33,'Additional Information'!$A:$B,2,0)),"",_xlfn.IFNA(VLOOKUP($J33,'Additional Information'!$A:$B,2,0),"")) | L33: Autofill from Additional information
B34: Name | C34: =IF(ISBLANK('Personal Information'!B31),"",'Personal Information'!B31) | F34: Required Qualifications: * | J34: Major Course of Study | K34: =IF(ISBLANK(VLOOKUP($J34,'Additional Information'!$A:$B,2,0)),"",_xlfn.IFNA(VLOOKUP($J34,'Additional Information'!$A:$B,2,0),"")) | L34: Autofill from Additional information
B35: Address | C35: =IF(ISBLANK('Personal Information'!B32),"",'Personal Information'!B32) | F35: Role and Responsibilities: | J35: =IF(K34="Accounting","Passed CPA Exam?*","") | K35: YES | L35: Manual- Required to fill
B36: Contact Info | C36: =IF(ISBLANK('Personal Information'!B33),"",'Personal Information'!B33) | F36: Client Endorsement Required * | J36: Special Skills or Qualifications | K36: =IF(ISBLANK(VLOOKUP($J36,'Additional Information'!$A:$B,2,0)),"",_xlfn.IFNA(VLOOKUP($J36,'Additional Information'!$A:$B,2,0),"")) | L36: Autofill from Additional information
B37: Collegiate | F37: Billable to Client | J37: Why Choosing Connext? | K37: =IF(ISBLANK(VLOOKUP($J37,'Additional Information'!$A:$B,2,0)),"",_xlfn.IFNA(VLOOKUP($J37,'Additional Information'!$A:$B,2,0),"")) | L37: Autofill from Additional information
B38: Degree/Course | C38: =IF(ISBLANK('Personal Information'!G34),"",'Personal Information'!G34) | F38: Degree Required? | J38: Travel Time to our Office (Min) * | K38: =IF(ISBLANK(VLOOKUP($J38,'Additional Information'!$A:$B,2,0)),"",_xlfn.IFNA(VLOOKUP($J38,'Additional Information'!$A:$B,2,0),"")) | L38: Autofill from Additional information
B39: Inclusive Dates | C39: =IF(ISBLANK('Personal Information'!I34),"",'Personal Information'!I34) | F39: Specify Field(s)* | J39: Own Transportation | K39: =IF(ISBLANK(VLOOKUP($J39,'Additional Information'!$A:$B,2,0)),"",_xlfn.IFNA(VLOOKUP($J39,'Additional Information'!$A:$B,2,0),"")) | L39: Autofill from Additional information
B40: Name | C40: =IF(ISBLANK('Personal Information'!B35),"",'Personal Information'!B35) | F40: Fresh Grad Ok? | J40: =IF($K39="NO", "Mode of Transportation*","") | K40: =IF(ISBLANK(VLOOKUP($J40,'Additional Information'!$A:$B,2,0)),"",_xlfn.IFNA(VLOOKUP($J40,'Additional Information'!$A:$B,2,0),"")) | L40: Autofill from Additional information
...

Sheet How to
B2: How to fill the field details
B3: Please do rename or SAVE as for the file name with the sample format [Sample: Juan_Luna_DelaCruz_Recruitment Form]
B4: Fill in only blank fields below or after the question field
B5: If not related, leave blank or enter NA
B6: Enter only whole numbers for contact numbers, government IDs and other fields with numbers
B7: Birthdate enter MMM DD, YYYY [Sample: Jan 01, 2000]

Sheet Personal Information
A6: PERSONAL INFORMATION
A7: Last Name | C7: Maiden Name | E7: First Name | G7: Middle Name | I7: Nickname
A9: Present Address | F9: Permanent Address
A18: Contact Number(s) | F18: Email Address
A20: Current Monthly Salary | E20: The following conditions may be required at some point in your employment. Are you amenable to working: | H20: Type of Employment
A21: Expected Salary
A22: Date Available (please specify Notice Period | E22: Shifts | H22: How did you know about us?
A23: Government Numbers | E23: Graveyard Shift
A24: SSS Number | E24: Rotation Schedule
A25: Tin | E25: Overtime | H25: Please Specify: Jobsteet.com
A26: Pag Ibig | E26: Holidays
A27: Date of Birth | C27: Citizenship | F27: Gender | H27: Civil Status
A29: EDUCATIONAL BACKGROUND | G29: Degree/Course | I29: Inclusive Dates
A30: Secondary
A31: Name
A32: Address
A33: Contact Info
A34: Collegiate
A35: Name
A36: Address
A37: Contact Info
A38: Post Graduate/Professional/Others
A39: Name
A40: Address
A41: Contact Info
A42: FAMILY HISTORY
B43: Name | F43: Occupation | H43: Employer/School
A44: Father
A45: Mother
A46: Brothers/Sisters
A51: Spouse
A52: Child/Children

Sheet Employment History
A1: EMPLOYMENT HISTORY
A2: Company Name | E2: Contact Details (Tel #, Email)
A3: Address
A4: Position | D4: Inclusive dates | G4: Monthly Salary
A5: Reason for leaving
A7: Company Name | B7: Taskus Inc | E7: Contact Details (Tel #, Email)
A8: Address
A9: Position | D9: Inclusive dates | G9: Monthly Salary
A10: Reason for leaving
A12: Company Name | E12: Contact Details (Tel #, Email)
A13: Address
A14: Position | D14: Inclusive dates | G14: Monthly Salary
A15: Reason for leaving
A16: TRAINING AND CERTIFICATION
A17: Course/Title | C17: Description | E17: Inclusive dates | G17: Training Institution
A22: SKILLS AND INTEREST
A23: Softwate Knowledge | E23: Equipment Knowledge
A24: Typing | E24: Professional Licenses and Memberships
A25: Language Fluency
A26: Please rate 1-5, 5 being the highest | C26: Spoken | D26: Written | E26: Other Skills (please specify)
A27: English
E28: Have you ever had any International exposure/travel Experience? (Please Specify)
A32: OTHERS
A33: Are you related to any person presently connnected with Connext? | H33: No
A34: Name and Relationship
A35: Have you had any criminal or civil liability? | H35: No
A36: Please specify
A37: REFERRALS
A38: Name | C38: Phone # | F38: Email Address
A44: CHARACTER REFERENCE
A45: PREVIOUS EMPLOYMENT
A46: Name | C46: Company | E46: Position | G46: Contact No(s)
A50: COLLEGE DEAN / SCHOOL REGISTRAR
A51: Name | C51: Company | E51: Position | G51: Contact No(s)
A54: Reference #

Sheet Essay
A1: Please write a short narrative on the question: (min, 100 words)
A2: Compose in no more than 100 words everything you want us to know about you. Include your work behavior strengths ans weaknesses, your expectations towards the company, your office mates and superiors. State also your future plans and goals in life (Alt + Enter to make another paragraph)
A25: OTHERS
A26: Are you related to any person presently connnected with Connext? | H26: No
A27: Name and Relationship
A28: In case of Emergency Contact Information
A29: Have you had any criminal or civil liability? | H29: No
A30: Please specify
A31: REFERRALS
A32: Name | C32: Phone # | F32: Email Address

Sheet Additional Information
A1: Additional information | * Required
A2: Head of Household *
A3: Number of Dependents *
A4: Date Willing to Start *
A5: Start Date on Last Job
A6: End Date on Last Job
A7: Still with Last Employer
A8: Number of Jobs in Last 3 Years *
A9: Reason for Leaving Last Job
A10: Notice Period (Days)
A11: High School Graduate
A12: Attended College
... A19: Own Transportation
A20: =IF($B19="NO", "Mode of Transportation*","-") -> -
A21: =IF($B19="NO","Number of Vehicles*","--") -> --
A22: Valid Passport *
A23: =IF(B22="YES","Valid US Visa*","")
A24: =IF(B22="YES","Former OFW*","")
A25: Current (Base) Salary * | B25: ='Personal Information'!C20 -> 0
A26: Desired Salary * | B26: ='Personal Information'!C21 -> 0

Sheet Ref Select
A1: Account endorsed to | B1: Source of Applicant * | C1: Gender * | D1: Head of Household * | E1: Number of Dependents * Number of Dependents * Number of Dependents * | F1: Number of Jobs in Last 3 Years | G1: Degree Obtained | H1: Major Course of Study | I1: Why Choosing Connext? | J1: Own Transportation | K1: Mode of Transportation* | L1: Valid Passport * | M1: Recruiter Recommendation | N1: Explain Reason: | O1: Professional Appearance? | P1: Attitute Towards Position? | Q1: Essay Quality | R1: Vebal Communication | S1: Ops Interview Disposition | T1: Client Interview Disposition | U1: Referral | V1: Passed CPA | W1: Check | X1: Reason for Leaving Last Job | Y1: No No "Return Response" | AA1: =AB1 -> 286 | AB1: =RIGHT(AC1,3)*1 -> 286 | AC1: Job Opening #286 | AF1: Job Opening
A2: ACE MEDICAL | B2: Academic Referrals | C2: Female | D2: Yes | E2: 0 | F2: 0 | G2: Associates | H2: Accounting | I2: Benefits | J2: Yes | K2: Ride Share | L2: Yes | M2: Hire | N2: Better internal/external hire options | O2: Provocative | P2: Complaints and Conditions | Q2: Poorly Written | R2: Prefers to speak in Local Vernacular | S2: Reject | T2: Reject | U2: Academic Referrals | V2: YES | W2: ü | X2: Birth or Child Care | AC2: PROFESSIONAL QUESTIONS | AF2: 256
A3: Aiea Pediatric Dental Center | B3: CDC Clark | C3: Male | D3: No | E3: 1 | F3: 1 | G3: BA or BS | H3: Agriculture, Agriculture Operations, and Related Sciences | I3: Challenge | J3: No | K3: Jeepney | L3: No | M3: Hold | N3: Does Not Speak English | O3: Casual | P3: Hard to Tell | Q3: Some Errors, but Acceptable | R3: English with noticeable grammar errors | S3: Hold Pending Other Candidates | T3: Hold Pending Other Candidates | U3: Community Networking | V3: NO | X3: Comp/Benefits | AC3: Screening Question 1 | AF3: 283
A4: AKAMAI | B4: Community Networking | E4: 2 | F4: 2 | G4: Masters | H4: Architecture and Related Services | I4: Culture / Working Environment | K4: Bus | M4: Reject and Pool | N4: High risk points (Start SMART) | O4: Business or Smart Casual | P4: Enthusiastic | Q4: Well Written | R4: Clearly understandable | S4: Recommend to Client | T4: Ok to Hire | U4: Employee Referral (Unqualified) | V4: Not Eligible | X4: Company Sold/Merged/Closed | Y4: 1 | AB4: =(1&AB1)*1 -> 1286 | AC4: How do you handle pressure at work especially when meeting deadlines? | AF4: 286
A5: ALIKAI HEALTH LLC | B5: Craigslist | E5: 3 | F5: 3 | G5: CPA | H5: Area, Ethnic, Cultural, Gender, and Group Studies | I5: Facility | K5: Trike | M5: Client Evaluation Recommended | N5: Irrelevant skills or experience | O5: Business Attire | S5: Ok to Hire | U5: Employee Referral Program | X5: Contract Ended | AC5: Response | AF5: 290
A6: Aloha Wound Care | B6: Employee Referral (resigned) | E6: 4 | F6: 4 | G6: PHD | H6: Aviation | I6: Jobs within Field | K6: Taxi | N6: Lack of enthusiasm | U6: Headhunter/Partner | X6: Disagreed with Management | Y6: 1 | AC6: Screening Question 2 | AF6: 291
A7: Ambulnz | B7: Employee Referral (Unqualified) | E7: 5 | F7: 5 | G7: Other (See Special Skills) | H7: Biological and Biomedical Sciences | I7: Just Need a Job / Applied Various Places | K7: Grab | N7: Made unrealistic salary/pay demands | U7: Temp Agency | X7: FRESH GRADUATE | Y7: 1 | AB7: =(2&AB1)*1 -> 2286 | AC7: Are you amenable to work on mid shift or night shift? | AF7: 292
A8: American Electric | B8: Employee Referral Program | E8: 6 | F8: 6 | H8: Business | I8: Location or Convenience | K8: Multiple | N8: Negative comments about past employer | X8: Illness | AC8: Response | AF8: 293
A9: ASB | B9: Existing Employee | E9: 7 | F9: 7 | H9: Business, Management, Marketing, and Related Support Services | I9: Recognition and Growth | K9: Other | N9: Not able to supply references | X9: Job Not in Field | Y9: 1 | AC9: Screening Question 3 | AF9: 294
A10: Atlantic Broadband | B10: Facebook | E10: 8 | F10: 8 | H10: Communication, Journalism, and Related Programs | I10: Referred by Family or Friend | N10: Poor references | X10: NEW TO WORKFORCE | Y10: 1 | AB10: =(3&AB1)*1 -> 3286 | AC10: How comfortable are you working with foreign clients? | AF10: 296
A11: Brayn Consulting | B11: Flyer from Solicitor | E11: 9 | F11: 9 | H11: Communications Technologies/technicians and Support Services | I11: Reputation and Brand | N11: Poor test scores | X11: No Growth Opportunities | Y11: 1 | AC11: Response | AF11: 297
A12: Business Development | B12: Headhunter/Partner | E12: 10 | F12: 10 | H12: Computer and Information Sciences and Support Services | I12: Salary | N12: Poor verbal/written communication | X12: Personal Reasons | AF12: 298
A13: Connext Staff | B13: Indeed.com | E13: 11 | F13: 11 | H13: Construction Trades | I13: Working Hours | N13: Qualified - Will continue to interview candidates | X13: Relocation | AA13: =AB13 -> 256 | AB13: =RIGHT(AC13,3)*1 -> 256 | AC13: Job Opening #256 | AF13: 299
A14: Dougherty Laser Vision | B14: Internal/Transfer | E14: 12 | F14: 12 | H14: Education | N14: Showed up very late (no valid reason) | X14: Returned to School | AC14: PROFESSIONAL QUESTIONS | AF14: 300
A15: Dr. Wade Takenishi | B15: Job Fair or Open House | E15: 13 | F15: 13 | H15: Engineering | N15: Speaks English, but struggles | X15: Started Business | AC15: Screening Question 1 | AF15: 301
A16: ECA ADVISORS | B16: Jobstreet | E16: 14 | F16: 14 | H16: Engineering Technologies and Engineering-Related Fields | N16: Unable or Unwilling to meet pre-hire requirements | X16: STILL WITH LAST EMPLOYER | Y16: 1 | AB16: =(1&AB13)*1 -> 1256 | AC16: What resources do you use (e.g. forums, websites and books) to keep up-to-date with engineering trends? | AF16: 302
A17: EJDA Services Inc. | B17: LinkedIn | E17: 15 | F17: 15 | H17: English Language and Literature/letters | N17: Unable to follow job application directions | X17: Stressful Work | Y17: 1 | AC17: Response | AF17: 303
A18: Eleyae Systems | B18: Monster.com | H18: Family and Consumer Sciences/human Sciences | N18: Under or over qualified | X18: Terminated - Performance | Y18: 1 | AC18: Screening Question 2 | AF18: 304
A19: Financial Services | B19: OJT | H19: Foreign Languages, Literatures, and Linguistics | X19: Terminated - Policy Violation | Y19: 1 | AB19: =(2&AB13)*1 -> 2256 | AC19: What types of problems have you encountered most often in operational systems after deployment? | AF19: 305
A20: FinLync | B20: Public Referral | H20: Health Professions and Related Programs | X20: Travel Distance | AC20: Response | AF20: 306
A21: Great Falls | B21: Recruiting Database | H21: History | X21: Work Hours | AC21: Screening Question 3 | AF21: 307
A22: HAM | B22: Tarpulin | H22: Homeland Security, Law Enforcement, Firefighting | AB22: =(3&AB13)*1 -> 3256 | AC22: Describe a time when you had to make a presentation. How did you manage to explain technical details to a non-technical audience? | AF22: 308
A23: HappyDoors Property Management | B23: Temp Agency | H23: Human Services | AC23: Response | AF23: 309
A24: Hawaii Endodontics | B24: Walk-In | H24: Legal Professions and Studies | AF24: 310
A25: Hawaii Pacific | B25: Website | H25: Liberal Arts and Sciences Studies and Humanities | AA25: =AB25 -> 283 | AB25: =RIGHT(AC25,3)*1 -> 283 | AC25: Job Opening #283 | AF25: 311
A26: HAWKTREE | B26: Word of mouth | H26: Library Science | AC26: PROFESSIONAL QUESTIONS
A27: HEALTHCARE | B27: Workbank | H27: Mathematics and Statistics | AC27: Screening Question 1
A28: HI SMILE ORTH | H28: Mechanic and Repair Technologies/technicians | AB28: =(1&AB25)*1 -> 1283 | AC28: Are you amendable to work on Hawaii Hours?
A29: HIBH | H29: Military Technologies and Applied Sciences | AC29: Response
A30: Hicks Pension | H30: Multi/interdisciplinary Studies | AC30: Screening Question 2
A31: Honolulu Disposal Service Inc | H31: Natural Resources and Conservation | AB31: =(2&AB25)*1 -> 2283 | AC31: What is customer service for you?
A32: HR Services | H32: Parks, Recreation, Leisure, and Fitness Studies | AC32: Response
A33: HR/Admin | H33: Personal and Culinary Services | AC33: Screening Question 3
A34: Island Healthcare Solutions | H34: Philosophy and Religious Studies | AB34: =(3&AB25)*1 -> 3283 | AC34: Describe a time when you received bad customer service and how did you deal with it?
A35: Jack in the Box | H35: Physical Sciences | AC35: Response
A36: K&K | H36: Precision Production
A37: Kidshine Pediatric Dental Group | H37: Psychology | AA37: =AB37 -> 292 | AB37: =RIGHT(AC37,3)*1 -> 292 | AC37: Job Opening #292
A38: KOHA | H38: Science Technologies/technicians | AC38: PROFESSIONAL QUESTIONS
A39: KOHA DV | H39: Social Sciences | AC39: Screening Question 1
A40: La Croix | H40: Theology and Religious Vocations | AB40: =(1&AB37)*1 -> 1292 | AC40: How do you handle pressure at work especially when meeting deadlines?
...

Sheet Sheet1
A1: </option> | D1: {=_xlfn._xlws.SORT(C2:C42)} | L1: <option value=''></option>
B2: Benefits</option> | C2: =SUBSTITUTE(SUBSTITUTE(SUBSTITUTE(B2,$L$1,""),$L$2,""),$L$3,"") -> Benefits | L2: <option value='Connext Staff'>
B3: Challenge</option> | C3: =SUBSTITUTE(SUBSTITUTE(SUBSTITUTE(B3,$L$1,""),$L$2,""),$L$3,"") -> Challenge | L3: </option>
B4: Culture / Working Environment</option> | C4: =SUBSTITUTE(SUBSTITUTE(SUBSTITUTE(B4,$L$1,""),$L$2,""),$L$3,"") -> Culture / Working Environment
B5: Facility</option> | C5: =SUBSTITUTE(SUBSTITUTE(SUBSTITUTE(B5,$L$1,""),$L$2,""),$L$3,"") -> Facility
B6: Jobs within Field</option> | C6: =SUBSTITUTE(SUBSTITUTE(SUBSTITUTE(B6,$L$1,""),$L$2,""),$L$3,"") -> Jobs within Field
B7: Just Need a Job / Applied Various Places</option> | C7: =SUBSTITUTE(SUBSTITUTE(SUBSTITUTE(B7,$L$1,""),$L$2,""),$L$3,"") -> Just Need a Job / Applied Various Places
B8: Location or Convenience</option> | C8: =SUBSTITUTE(SUBSTITUTE(SUBSTITUTE(B8,$L$1,""),$L$2,""),$L$3,"") -> Location or Convenience
B9: Recognition and Growth</option> | C9: =SUBSTITUTE(SUBSTITUTE(SUBSTITUTE(B9,$L$1,""),$L$2,""),$L$3,"") -> Recognition and Growth
B10: Referred by Family or Friend</option> | C10: =SUBSTITUTE(SUBSTITUTE(SUBSTITUTE(B10,$L$1,""),$L$2,""),$L$3,"") -> Referred by Family or Friend
B11: Reputation and Brand</option> | C11: =SUBSTITUTE(SUBSTITUTE(SUBSTITUTE(B11,$L$1,""),$L$2,""),$L$3,"") -> Reputation and Brand
B12: Salary</option> | C12: =SUBSTITUTE(SUBSTITUTE(SUBSTITUTE(B12,$L$1,""),$L$2,""),$L$3,"") -> Salary
B13: Working Hours</option> | C13: =SUBSTITUTE(SUBSTITUTE(SUBSTITUTE(B13,$L$1,""),$L$2,""),$L$3,"") -> Working Hours
C14: =SUBSTITUTE(SUBSTITUTE(SUBSTITUTE(B14,$L$1,""),$L$2,""),$L$3,"")
C15: =SUBSTITUTE(SUBSTITUTE(SUBSTITUTE(B15,$L$1,""),$L$2,""),$L$3,"")
C16: =SUBSTITUTE(SUBSTITUTE(SUBSTITUTE(B16,$L$1,""),$L$2,""),$L$3,"")
C17: =SUBSTITUTE(SUBSTITUTE(SUBSTITUTE(B17,$L$1,""),$L$2,""),$L$3,"")
C18: =SUBSTITUTE(SUBSTITUTE(SUBSTITUTE(B18,$L$1,""),$L$2,""),$L$3,"")
C19: =SUBSTITUTE(SUBSTITUTE(SUBSTITUTE(B19,$L$1,""),$L$2,""),$L$3,"")
C20: =SUBSTITUTE(SUBSTITUTE(SUBSTITUTE(B20,$L$1,""),$L$2,""),$L$3,"")
C21: =SUBSTITUTE(SUBSTITUTE(SUBSTITUTE(B21,$L$1,""),$L$2,""),$L$3,"")
C22: =SUBSTITUTE(SUBSTITUTE(SUBSTITUTE(B22,$L$1,""),$L$2,""),$L$3,"")
C23: =SUBSTITUTE(SUBSTITUTE(SUBSTITUTE(B23,$L$1,""),$L$2,""),$L$3,"")
C24: =SUBSTITUTE(SUBSTITUTE(SUBSTITUTE(B24,$L$1,""),$L$2,""),$L$3,"")
C25: =SUBSTITUTE(SUBSTITUTE(SUBSTITUTE(B25,$L$1,""),$L$2,""),$L$3,"")
... C29: =SUBSTITUTE(SUBSTITUTE(SUBSTITUTE(B29,$L$1,""),$L$2,""),$L$3,"")
C30: =SUBSTITUTE(SUBSTITUTE(SUBSTITUTE(B30,$L$1,""),$L$2,""),$L$3,"") | D30: Benefits
C31: =SUBSTITUTE(SUBSTITUTE(SUBSTITUTE(B31,$L$1,""),$L$2,""),$L$3,"") | D31: Challenge
C32: =SUBSTITUTE(SUBSTITUTE(SUBSTITUTE(B32,$L$1,""),$L$2,""),$L$3,"") | D32: Culture / Working Environment
C33: =SUBSTITUTE(SUBSTITUTE(SUBSTITUTE(B33,$L$1,""),$L$2,""),$L$3,"") | D33: Facility
C34: =SUBSTITUTE(SUBSTITUTE(SUBSTITUTE(B34,$L$1,""),$L$2,""),$L$3,"") | D34: Jobs within Field
C35: =SUBSTITUTE(SUBSTITUTE(SUBSTITUTE(B35,$L$1,""),$L$2,""),$L$3,"") | D35: Just Need a Job / Applied Various Places
C36: =SUBSTITUTE(SUBSTITUTE(SUBSTITUTE(B36,$L$1,""),$L$2,""),$L$3,"") | D36: Location or Convenience
C37: =SUBSTITUTE(SUBSTITUTE(SUBSTITUTE(B37,$L$1,""),$L$2,""),$L$3,"") | D37: Recognition and Growth
C38: =SUBSTITUTE(SUBSTITUTE(SUBSTITUTE(B38,$L$1,""),$L$2,""),$L$3,"") | D38: Referred by Family or Friend
C39: =SUBSTITUTE(SUBSTITUTE(SUBSTITUTE(B39,$L$1,""),$L$2,""),$L$3,"") | D39: Reputation and Brand
C40: =SUBSTITUTE(SUBSTITUTE(SUBSTITUTE(B40,$L$1,""),$L$2,""),$L$3,"") | D40: Salary
C41: =SUBSTITUTE(SUBSTITUTE(SUBSTITUTE(B41,$L$1,""),$L$2,""),$L$3,"") | D41: Working Hours
C42: =SUBSTITUTE(SUBSTITUTE(SUBSTITUTE(B42,$L$1,""),$L$2,""),$L$3,"")
C43: =SUBSTITUTE(SUBSTITUTE(SUBSTITUTE(B43,$L$1,""),$L$2,""),$L$3,"")
...
